
<?xml version="1.0" ?> <!-- =================================================================================== --> <!-- | This document was autogenerated by xacro from jetsoncar.xacro | --> <!-- | EDITING THIS FILE BY HAND IS NOT RECOMMENDED | --> <!-- =================================================================================== --> <robot name="jetsoncar" xmlns:xacro="http://www.ros.org/wiki/xacro"> <material name="black"> <color rgba="0.0 0.0 0.0 1.0"/> </material> <material name="blue"> <color rgba="0.0 0.0 0.8 1.0"/> </material> <material name="green"> <color rgba="0.0 0.8 0.0 1.0"/> </material> <material name="grey"> <color rgba="0.2 0.2 0.2 1.0"/> </material> <material name="orange"> <color rgba="1.0 0.423529411765 0.0392156862745 1.0"/> </material> <material name="brown"> <color rgba="0.870588235294 0.811764705882 0.764705882353 1.0"/> </material> <material name="red"> <color rgba="0.8 0.0 0.0 1.0"/> </material> <material name="white"> <color rgba="1.0 1.0 1.0 1.0"/> </material> <material name="acrylic"> <color rgba="1.0 1.0 1.0 0.4"/> </material> <link name="base_link"/> <link name="imu"> <visual> <geometry> <box size="0.05 0.05 0.03"/> <!-- 50x50x30 mm, Please confirm against 3D drawings --> </geometry> <origin rpy="0 0 0" xyz="0 0 0"/> <!-- origin (0,0,0) is in the center of the box --> <material name="grey"/> </visual> </link> <link name="baseplate"> <visual> <geometry> <box size="0.50 0.20 0.0675"/> <!-- 50x20x6.75 cm, X-axis is front of vehicle --> </geometry> <origin rpy="0 0 0" xyz="0 0 0.03375"/> <!-- origin (0,0,0) is in the center of the box --> <material name="acrylic"/> </visual> </link> <link name="front_mount"> <visual> <geometry> <box size="0.24 0.12 0.01"/> </geometry> <origin rpy="0 0.5 0" xyz="0 0 0"/> <!-- origin (0,0,0) is in the center of the box --> <material name="grey"/> </visual> </link> <link name="rear_mount"> <visual> <geometry> <box size="0.24 0.12 0.01"/> </geometry> <origin rpy="0 -0.5 0" xyz="0 0 0"/> <!-- origin (0,0,0) is in the center of the box --> <material name="grey"/> </visual> </link> <link name="rear_shaft"> <visual> <geometry> <cylinder length="0.285" radius="0.018"/> <!-- confirm length between wheels --> </geometry> <origin rpy="1.570796327 0 0" xyz="0 0 0"/> <!-- origin (0,0,0) is in the center of the cylinder --> <material name="black"/> </visual> </link> <link name="front_shaft"> <visual> <geometry> <cylinder length="0.285" radius="0.018"/> <!-- confirm length between wheels --> </geometry> <origin rpy="1.570796327 0 0" xyz="0 0 0"/> <!-- origin (0,0,0) is in the center of the cylinder --> <material name="black"/> </visual> </link> <link name="front_right_bearing"> <visual> <geometry> <sphere radius="0.015"/> </geometry> <origin rpy="0 0 0" xyz="0 0 0"/> <!-- origin (0,0,0) is in the center of the cylinder --> <material name="white"/> </visual> </link> <link name="front_right_wheel"> <visual> <geometry> <cylinder length="0.064" radius="0.0775"/> </geometry> <origin rpy="1.570796327 0 0" xyz="0 0 0"/> <!-- origin (0,0,0) is in the center of the cylinder --> <material name="black"/> </visual> </link> <link name="front_left_bearing"> <visual> <geometry> <sphere radius="0.015"/> </geometry> <origin rpy="0 0 0" xyz="0 0 0"/> <!-- origin (0,0,0) is in the center of the cylinder --> <material name="white"/> </visual> </link> <link name="front_left_wheel"> <visual> <geometry> <cylinder length="0.064" radius="0.0775"/> </geometry> <origin rpy="1.570796327 0 0" xyz="0 0 0"/> <!-- origin (0,0,0) is in the center of the cylinder --> <material name="black"/> </visual> </link> <link name="rear_right_wheel"> <visual> <geometry> <cylinder length="0.064" radius="0.0775"/> </geometry> <origin rpy="1.570796327 0 0" xyz="0 0 0"/> <!-- origin (0,0,0) is in the center of the cylinder --> <material name="black"/> </visual> </link> <link name="rear_left_wheel"> <visual> <geometry> <cylinder length="0.064" radius="0.0775"/> </geometry> <origin rpy="1.570796327 0 0" xyz="0 0 0"/> <!-- origin (0,0,0) is in the center of the cylinder --> <material name="black"/> </visual> </link> <joint name="baselink_to_baseplate" type="fixed"> <parent link="base_link"/> <child link="baseplate"/> <origin rpy="0 0 0" xyz="0 0 0"/> <!-- offset from parent to child, so with direction based in parent frame --> </joint> <joint name="baseplate_to_imu" type="fixed"> <parent link="baseplate"/> <child link="imu"/> <origin rpy="0 0 0" xyz="0 0 0.015"/> <!-- offset from parent to child, so with direction based in parent frame --> </joint> <joint name="baseplate_to_front_mount" type="fixed"> <parent link="baseplate"/> <child link="front_mount"/> <origin rpy="0 0 0" xyz="0.105 0 -0.059"/> <!-- offset from parent to child, so with direction based in parent frame --> </joint> <joint name="front_mount_to_front_shaft" type="fixed"> <parent link="front_mount"/> <child link="front_shaft"/> <origin rpy="0 0 0" xyz="0.105 0 -0.059"/> <!-- offset from parent to child, so with direction based in parent frame --> </joint> <joint name="baseplate_to_rear_mount" type="fixed"> <parent link="baseplate"/> <child link="rear_mount"/> <origin rpy="0 0 0" xyz="-0.105 0 -0.059"/> <!-- offset from parent to child, so with direction based in parent frame --> </joint> <joint name="rear_mount_to_rear_shaft" type="fixed"> <parent link="rear_mount"/> <child link="rear_shaft"/> <origin rpy="0 0 0" xyz="-0.105 0 -0.059"/> <!-- offset from parent to child, so with direction based in parent frame --> </joint> <joint name="front_right_bearing_joint" type="revolute"> <!-- revolute is a joint with a range limited motion around its' axis --> <parent link="front_shaft"/> <child link="front_right_bearing"/> <origin rpy="0 0 0" xyz="0 -0.1425 0"/> <!-- offset from parent to child, so with direction based in parent frame --> <axis xyz="0 0 1"/> <limit effort="1000" lower="-0.349065850399" upper="0.349065850399" velocity="0.5"/> </joint> <joint name="front_right_wheel_joint" type="continuous"> <!-- continuous is a joint of continous motion around its' axis --> <parent link="front_right_bearing"/> <child link="front_right_wheel"/> <origin rpy="0 0 0" xyz="0 0 0"/> <!-- offset from parent to child, so with direction based in parent frame --> <axis xyz="0 1 0"/> </joint> <joint name="front_left_bearing_joint" type="revolute"> <!-- revolute is a joint with a range limited motion around its' axis --> <parent link="front_shaft"/> <child link="front_left_bearing"/> <origin rpy="0 0 0" xyz="0 0.1425 0"/> <!-- offset from parent to child, so with direction based in parent frame --> <axis xyz="0 0 1"/> <limit effort="1000" lower="-0.349065850399" upper="0.349065850399" velocity="0.5"/> </joint> <joint name="front_left_wheel_joint" type="continuous"> <!-- continuous is a joint of continous motion around its' axis --> <parent link="front_left_bearing"/> <child link="front_left_wheel"/> <origin rpy="0 0 0" xyz="0 0 0"/> <!-- offset from parent to child, so with direction based in parent frame --> <axis xyz="0 1 0"/> </joint> <joint name="rear_right_wheel_joint" type="continuous"> <!-- continuous is a joint of continous motion around its' axis --> <parent link="rear_shaft"/> <child link="rear_right_wheel"/> <origin rpy="0 0 0" xyz="0 -0.1425 0"/> <!-- offset from parent to child, so with direction based in parent frame --> <axis xyz="0 1 0"/> </joint> <joint name="rear_left_wheel_joint" type="continuous"> <!-- continuous is a joint of continous motion around its' axis --> <parent link="rear_shaft"/> <child link="rear_left_wheel"/> <origin rpy="0 0 0" xyz="0 0.1425 0"/> <!-- offset from parent to child, so with direction based in parent frame --> <axis xyz="0 1 0"/> </joint> <!-- include the Gazebo description of the JetsonCar --> </robot>
